<robot name="raise_a2_t2d0">
    <link name="base_link">
    <inertial>
      <origin xyz="-0.07245655 -0.00043996 0.16664738" rpy="0 0 0" />
      <mass value="17.71410976" />
      <inertia ixx="0.56785982" iyy="0.52650076" izz="0.17272833" ixy="0.00042996" ixz="0.00807567" iyz="-0.00000077"/>
    </inertial>
    <visual>
      <origin xyz="0 0 0" rpy="0 0 0" />
      <geometry>
        <mesh filename="file:///home/lizhen/works/open_source/robot_model_generator/src/model_generator/robot_data/meshes/body.STL" scale="1 1 1"/>
      </geometry>
      <material name="">
        <color rgba="0.8 0.4 0 1" />
      </material>
    </visual>
    <collision>
      <origin xyz="0 0 0" rpy="0 0 0"/>
      <geometry>
        <mesh filename="file:///home/lizhen/works/open_source/robot_model_generator/src/model_generator/robot_data/meshes/body.STL" scale="1 1 1"/>
      </geometry>
    </collision>
</link>

<link name="left_hip_roll">
    <inertial>
      <origin xyz="0.00011252 0.02130615 -0.07465143" rpy="0 0 0" />
      <mass value="2.39059365" />
      <inertia ixx="0.00381223" iyy="0.00368166" izz="0.00334373" ixy="-0.00000253" ixz="0.00000433" iyz="0.00019809"/>
    </inertial>
    <visual>
      <origin xyz="0 0 0" rpy="0 0 0" />
      <geometry>
        <mesh filename="file:///home/lizhen/works/open_source/robot_model_generator/src/model_generator/robot_data/meshes/left_leg_hip_roll.STL" scale="1 1 1"/>
      </geometry>
      <material name="">
        <color rgba="1 0.4 0.4 1" />
      </material>
    </visual>
    <collision>
      <origin xyz="0 0 0" rpy="0 0 0"/>
      <geometry>
        <mesh filename="" scale="1 1 1"/>
      </geometry>
    </collision>
</link>

<joint name="idx01_left_hip_roll" type="revolute">
    <origin xyz="-0.0808 0.105 -0.0652" rpy="0.7854 0 1.5708" />
    <parent link="base_link" />
    <child link="left_hip_roll" />
    <axis xyz="0 0 1" />
    <limit lower="-0.698" upper="0.698" effort="120" velocity="12" />
</joint>

<link name="left_hip_yaw">
    <inertial>
      <origin xyz="-0.00012288 0.01576460 0.10828703" rpy="0 0 0" />
      <mass value="3.79911511" />
      <inertia ixx="0.00941292" iyy="0.01442888" izz="0.00698406" ixy="0.00000766" ixz="0.00000238" iyz="-0.00055185"/>
    </inertial>
    <visual>
      <origin xyz="0 0 0" rpy="0 0 0" />
      <geometry>
        <mesh filename="file:///home/lizhen/works/open_source/robot_model_generator/src/model_generator/robot_data/meshes/left_leg_hip_yaw.STL" scale="1 1 1"/>
      </geometry>
      <material name="">
        <color rgba="1 1 0.4 1" />
      </material>
    </visual>
    <collision>
      <origin xyz="0 0 0" rpy="0 0 0"/>
      <geometry>
        <mesh filename="" scale="1 1 1"/>
      </geometry>
    </collision>
</link>

<joint name="idx02_left_hip_yaw" type="revolute">
    <origin xyz="0 -0.017 -0.0682" rpy="1.5708 -1.5708 0" />
    <parent link="left_hip_roll" />
    <child link="left_hip_yaw" />
    <axis xyz="0 0 1" />
    <limit lower="-1.57" upper="1.57" effort="120" velocity="12" />
</joint>

<link name="left_hip_pitch">
    <inertial>
      <origin xyz="-0.05844086 0.00492907 0.02304337" rpy="0 0 0" />
      <mass value="5.30562514" />
      <inertia ixx="0.01185844" iyy="0.07032698" izz="0.07514457" ixy="0.00347724" ixz="-0.00657871" iyz="0.00060915"/>
    </inertial>
    <visual>
      <origin xyz="0 0 0" rpy="0 0 0" />
      <geometry>
        <mesh filename="file:///home/lizhen/works/open_source/robot_model_generator/src/model_generator/robot_data/meshes/left_leg_hip_pitch.STL" scale="1 1 1"/>
      </geometry>
      <material name="">
        <color rgba="0.4 1 0.4 1" />
      </material>
    </visual>
    <collision>
      <origin xyz="0 0 0" rpy="0 0 0"/>
      <geometry>
        <mesh filename="" scale="1 1 1"/>
      </geometry>
    </collision>
</link>

<joint name="idx03_left_hip_pitch" type="revolute">
    <origin xyz="0 -0.020 0.1205" rpy="1.5708 0.7854 0" />
    <parent link="left_hip_yaw" />
    <child link="left_hip_pitch" />
    <axis xyz="0 0 1" />
    <limit lower="-1.919862144" upper="0.78539815" effort="140" velocity="12" />
</joint>

<link name="left_knee">
    <inertial>
      <origin xyz="-0.17686628 0.00290708 -0.00002416" rpy="0 0 0" />
      <mass value="2.78469232" />
      <inertia ixx="0.00224858" iyy="0.02247360" izz="0.02359583" ixy="-0.00064522" ixz="0.00034901" iyz="-0.00000111"/>
    </inertial>
    <visual>
      <origin xyz="0 0 0" rpy="0 0 0" />
      <geometry>
        <mesh filename="file:///home/lizhen/works/open_source/robot_model_generator/src/model_generator/robot_data/meshes/left_leg_knee.STL" scale="1 1 1"/>
      </geometry>
      <material name="">
        <color rgba="0 0.5 1 1" />
      </material>
    </visual>
    <collision>
      <origin xyz="0 0 0" rpy="0 0 0"/>
      <geometry>
        <mesh filename="" scale="1 1 1"/>
      </geometry>
    </collision>
</link>

<joint name="idx04_left_knee" type="revolute">
    <origin xyz="-0.34 0 0" rpy="0 0 0" />
    <parent link="left_hip_pitch" />
    <child link="left_knee" />
    <axis xyz="0 0 1" />
    <limit lower="-0.087266461" upper="2.443460911" effort="140" velocity="12" />
</joint>

<link name="left_toe_pitch">
    <inertial>
      <origin xyz="0 0 0" rpy="0 0 0" />
      <mass value="0.08772028" />
      <inertia ixx="0.00001572" iyy="0.00001128" izz="0.00001148" ixy="0" ixz="0" iyz="0"/>
    </inertial>
    <visual>
      <origin xyz="0 0 0" rpy="0 0 0" />
      <geometry>
        <mesh filename="file:///home/lizhen/works/open_source/robot_model_generator/src/model_generator/robot_data/meshes/left_leg_toe_pitch.STL" scale="1 1 1"/>
      </geometry>
      <material name="">
        <color rgba="0.8 1.0 0.8 1" />
      </material>
    </visual>
    <collision>
      <origin xyz="0 0 0" rpy="0 0 0"/>
      <geometry>
        <mesh filename="" scale="1 1 1"/>
      </geometry>
    </collision>
</link>

<joint name="idx05_left_toe_pitch" type="revolute">
    <origin xyz="-0.377 0 0" rpy="0 0 0" />
    <parent link="left_knee" />
    <child link="left_toe_pitch" />
    <axis xyz="0 0 1" />
    <limit lower="-1.047197533" upper="0.523598767" effort="50" velocity="12" />
</joint>

<link name="left_toe_roll">
    <inertial>
      <origin xyz="-0.04183694 0.00003333 0.02612972" rpy="0 0 0" />
      <mass value="0.90432039" />
      <inertia ixx="0.00532431" iyy="0.00494869" izz="0.00073321" ixy="0.00000010" ixz="0.00024374" iyz="-0.00000302"/>
    </inertial>
    <visual>
      <origin xyz="0 0 0" rpy="0 0 0" />
      <geometry>
        <mesh filename="file:///home/lizhen/works/open_source/robot_model_generator/src/model_generator/robot_data/meshes/left_leg_foot.STL" scale="1 1 1"/>
      </geometry>
      <material name="">
        <color rgba="1 0.5 1 1" />
      </material>
    </visual>
    <collision>
      <origin xyz="0 0 0" rpy="0 0 0"/>
      <geometry>
        <mesh filename="" scale="1 1 1"/>
      </geometry>
    </collision>
</link>

<joint name="idx06_left_toe_roll" type="revolute">
    <origin xyz="0 0 0" rpy="-1.5707963 0 0" />
    <parent link="left_toe_pitch" />
    <child link="left_toe_roll" />
    <axis xyz="0 0 1" />
    <limit lower="-0.488692182" upper="0.488692182" effort="50" velocity="12" />
</joint>

<link name="left_toe_A">
    <inertial>
      <origin xyz="0.00009121 -0.01877013 -0.00172194" rpy="0 0 0" />
      <mass value="0.06362578" />
      <inertia ixx="0.00004436" iyy="0.00001212" izz="0.00005103" ixy="-0.00000004" ixz="-0.00000004" iyz="-0.00000800"/>
    </inertial>
    <visual>
      <origin xyz="0 0 0" rpy="0 0 0" />
      <geometry>
        <mesh filename="file:///home/lizhen/works/open_source/robot_model_generator/src/model_generator/robot_data/meshes/left_leg_rod1_long.STL" scale="1 1 1"/>
      </geometry>
      <material name="">
        <color rgba="1 0.4 0.4 1" />
      </material>
    </visual>
    <collision>
      <origin xyz="0 0 0" rpy="0 0 0"/>
      <geometry>
        <mesh filename="" scale="1 1 1"/>
      </geometry>
    </collision>
</link>

<joint name="idx07_left_toe_A" type="fixed">
    <origin xyz="-0.138 0 -0.0315" rpy="0 0 0" />
    <parent link="left_knee" />
    <child link="left_toe_A" />
    <axis xyz="0 0 1" />
    <limit lower="-1.5708" upper="1.5708" effort="0" velocity="0" />
</joint>

<link name="left_toe_A_rod">
    <inertial>
      <origin xyz="-0.11950000 0 -0.00001491" rpy="0 0 0" />
      <mass value="0.08203113" />
      <inertia ixx="0.00000228" iyy="0.00078598" izz="0.00078738" ixy="0" ixz="0" iyz="0"/>
    </inertial>
    <visual>
      <origin xyz="0 0 0" rpy="0 0 0" />
      <geometry>
        <mesh filename="file:///home/lizhen/works/open_source/robot_model_generator/src/model_generator/robot_data/meshes/left_leg_rod2_long.STL" scale="1 1 1"/>
      </geometry>
      <material name="">
        <color rgba="1 1 0.4 1" />
      </material>
    </visual>
    <collision>
      <origin xyz="0 0 0" rpy="0 0 0"/>
      <geometry>
        <mesh filename="" scale="1 1 1"/>
      </geometry>
    </collision>
</link>

<joint name="idx08_left_toe_A_rod" type="fixed">
    <origin xyz="0 -0.063 0" rpy="0 0 0" />
    <parent link="left_toe_A" />
    <child link="left_toe_A_rod" />
    <axis xyz="0 0 1" />
    <limit lower="0" upper="0" effort="0" velocity="0" />
</joint>

<link name="left_toe_B">
    <inertial>
      <origin xyz="-0.00009121 -0.01877013 0.00172194" rpy="0 0 0" />
      <mass value="0.06362578" />
      <inertia ixx="0.00004436" iyy="0.00001212" izz="0.00005103" ixy="0.00000004" ixz="-0.00000004" iyz="0.00000800"/>
    </inertial>
    <visual>
      <origin xyz="0 0 0" rpy="0 0 0" />
      <geometry>
        <mesh filename="file:///home/lizhen/works/open_source/robot_model_generator/src/model_generator/robot_data/meshes/left_leg_rod1_short.STL" scale="1 1 1"/>
      </geometry>
      <material name="">
        <color rgba="0.4 1 0.4 1" />
      </material>
    </visual>
    <collision>
      <origin xyz="0 0 0" rpy="0 0 0"/>
      <geometry>
        <mesh filename="" scale="1 1 1"/>
      </geometry>
    </collision>
</link>

<joint name="idx09_left_toe_B" type="fixed">
    <origin xyz="-0.232 0 0.0315" rpy="0 0 0" />
    <parent link="left_knee" />
    <child link="left_toe_B" />
    <axis xyz="0 0 1" />
    <limit lower="-1.5708" upper="1.5708" effort="0" velocity="0" />
</joint>

<link name="left_toe_B_rod">
    <inertial>
      <origin xyz="-0.07250000 0.00000653 -0.00002437" rpy="0 0 0" />
      <mass value="0.08225550" />
      <inertia ixx="0.00000274" iyy="0.00031414" izz="0.00031573" ixy="0" ixz="0" iyz="0"/>
    </inertial>
    <visual>
      <origin xyz="0 0 0" rpy="0 0 0" />
      <geometry>
        <mesh filename="file:///home/lizhen/works/open_source/robot_model_generator/src/model_generator/robot_data/meshes/left_leg_rod2_short.STL" scale="1 1 1"/>
      </geometry>
      <material name="">
        <color rgba="0 0.5 1 1" />
      </material>
    </visual>
    <collision>
      <origin xyz="0 0 0" rpy="0 0 0"/>
      <geometry>
        <mesh filename="" scale="1 1 1"/>
      </geometry>
    </collision>
</link>

<joint name="idx10_left_toe_B_rod" type="fixed">
    <origin xyz="0 -0.063 0" rpy="0 0 0" />
    <parent link="left_toe_B" />
    <child link="left_toe_B_rod" />
    <axis xyz="0 0 1" />
    <limit lower="0" upper="0" effort="0" velocity="0" />
</joint>

<link name="right_hip_roll">
    <inertial>
      <origin xyz="0.00011252 -0.02130615 -0.07465143" rpy="0 0 0" />
      <mass value="2.39059365" />
      <inertia ixx="0.00381223" iyy="0.00368166" izz="0.00334373" ixy="2.53e-06" ixz="4.33e-06" iyz="-0.00019809"/>
    </inertial>
    <visual>
      <origin xyz="0 0 0" rpy="0 0 0" />
      <geometry>
        <mesh filename="file:///home/lizhen/works/open_source/robot_model_generator/src/model_generator/robot_data/meshes/left_leg_hip_roll.STL" scale="1.0 -1.0 1.0"/>
      </geometry>
      <material name="">
        <color rgba="1 0.4 0.4 1" />
      </material>
    </visual>
    <collision>
      <origin xyz="0 0 0" rpy="0 0 0"/>
      <geometry>
        <mesh filename="" scale="1 1 1"/>
      </geometry>
    </collision>
</link>

<joint name="idx11_right_hip_roll" type="revolute">
    <origin xyz="-0.0808 -0.105 -0.0652" rpy="-0.7854 0.0 -1.5708" />
    <parent link="base_link" />
    <child link="right_hip_roll" />
    <axis xyz="0 0 1" />
    <limit lower="-0.698" upper="0.698" effort="120" velocity="12" />
</joint>

<link name="right_hip_yaw">
    <inertial>
      <origin xyz="-0.00012288 -0.0157646 0.10828703" rpy="0 0 0" />
      <mass value="3.79911511" />
      <inertia ixx="0.00941292" iyy="0.01442888" izz="0.00698406" ixy="-7.66e-06" ixz="2.38e-06" iyz="0.00055185"/>
    </inertial>
    <visual>
      <origin xyz="0 0 0" rpy="0 0 0" />
      <geometry>
        <mesh filename="file:///home/lizhen/works/open_source/robot_model_generator/src/model_generator/robot_data/meshes/left_leg_hip_yaw.STL" scale="1.0 -1.0 1.0"/>
      </geometry>
      <material name="">
        <color rgba="1 1 0.4 1" />
      </material>
    </visual>
    <collision>
      <origin xyz="0 0 0" rpy="0 0 0"/>
      <geometry>
        <mesh filename="" scale="1 1 1"/>
      </geometry>
    </collision>
</link>

<joint name="idx12_right_hip_yaw" type="revolute">
    <origin xyz="0.0 0.017 -0.0682" rpy="-1.5708 -1.5708 -0.0" />
    <parent link="right_hip_roll" />
    <child link="right_hip_yaw" />
    <axis xyz="0 0 1" />
    <limit lower="-1.57" upper="1.57" effort="120" velocity="12" />
</joint>

<link name="right_hip_pitch">
    <inertial>
      <origin xyz="-0.05844086 -0.00492907 0.02304337" rpy="0 0 0" />
      <mass value="5.30562514" />
      <inertia ixx="0.01185844" iyy="0.07032698" izz="0.07514457" ixy="-0.00347724" ixz="-0.00657871" iyz="-0.00060915"/>
    </inertial>
    <visual>
      <origin xyz="0 0 0" rpy="0 0 0" />
      <geometry>
        <mesh filename="file:///home/lizhen/works/open_source/robot_model_generator/src/model_generator/robot_data/meshes/left_leg_hip_pitch.STL" scale="1.0 -1.0 1.0"/>
      </geometry>
      <material name="">
        <color rgba="0.4 1 0.4 1" />
      </material>
    </visual>
    <collision>
      <origin xyz="0 0 0" rpy="0 0 0"/>
      <geometry>
        <mesh filename="" scale="1 1 1"/>
      </geometry>
    </collision>
</link>

<joint name="idx13_right_hip_pitch" type="revolute">
    <origin xyz="0.0 0.02 0.1205" rpy="-1.5708 0.7854 -0.0" />
    <parent link="right_hip_yaw" />
    <child link="right_hip_pitch" />
    <axis xyz="0 0 1" />
    <limit lower="-0.78539815" upper="1.919862144" effort="140" velocity="12" />
</joint>

<link name="right_knee">
    <inertial>
      <origin xyz="-0.17686628 -0.00290708 -2.416e-05" rpy="0 0 0" />
      <mass value="2.78469232" />
      <inertia ixx="0.00224858" iyy="0.02247360" izz="0.02359583" ixy="0.00064522" ixz="0.00034901" iyz="1.11e-06"/>
    </inertial>
    <visual>
      <origin xyz="0 0 0" rpy="0 0 0" />
      <geometry>
        <mesh filename="file:///home/lizhen/works/open_source/robot_model_generator/src/model_generator/robot_data/meshes/left_leg_knee.STL" scale="1.0 -1.0 1.0"/>
      </geometry>
      <material name="">
        <color rgba="0 0.5 1 1" />
      </material>
    </visual>
    <collision>
      <origin xyz="0 0 0" rpy="0 0 0"/>
      <geometry>
        <mesh filename="" scale="1 1 1"/>
      </geometry>
    </collision>
</link>

<joint name="idx14_right_knee" type="revolute">
    <origin xyz="-0.34 -0.0 0.0" rpy="-0.0 0.0 -0.0" />
    <parent link="right_hip_pitch" />
    <child link="right_knee" />
    <axis xyz="0 0 1" />
    <limit lower="-2.443460911" upper="0.087266461" effort="140" velocity="12" />
</joint>

<link name="right_toe_pitch">
    <inertial>
      <origin xyz="0.0 -0.0 0.0" rpy="0 0 0" />
      <mass value="0.08772028" />
      <inertia ixx="0.00001572" iyy="0.00001128" izz="0.00001148" ixy="-0.0" ixz="0.0" iyz="-0.0"/>
    </inertial>
    <visual>
      <origin xyz="0 0 0" rpy="0 0 0" />
      <geometry>
        <mesh filename="file:///home/lizhen/works/open_source/robot_model_generator/src/model_generator/robot_data/meshes/left_leg_toe_pitch.STL" scale="1.0 -1.0 1.0"/>
      </geometry>
      <material name="">
        <color rgba="0.8 1.0 0.8 1" />
      </material>
    </visual>
    <collision>
      <origin xyz="0 0 0" rpy="0 0 0"/>
      <geometry>
        <mesh filename="" scale="1 1 1"/>
      </geometry>
    </collision>
</link>

<joint name="idx15_right_toe_pitch" type="revolute">
    <origin xyz="-0.377 -0.0 0.0" rpy="-0.0 0.0 -0.0" />
    <parent link="right_knee" />
    <child link="right_toe_pitch" />
    <axis xyz="0 0 1" />
    <limit lower="-0.523598767" upper="1.047197533" effort="50" velocity="12" />
</joint>

<link name="right_toe_roll">
    <inertial>
      <origin xyz="-0.04183694 -3.333e-05 0.02612972" rpy="0 0 0" />
      <mass value="0.90432039" />
      <inertia ixx="0.00532431" iyy="0.00494869" izz="0.00073321" ixy="-1e-07" ixz="0.00024374" iyz="3.02e-06"/>
    </inertial>
    <visual>
      <origin xyz="0 0 0" rpy="0 0 0" />
      <geometry>
        <mesh filename="file:///home/lizhen/works/open_source/robot_model_generator/src/model_generator/robot_data/meshes/left_leg_foot.STL" scale="1.0 -1.0 1.0"/>
      </geometry>
      <material name="">
        <color rgba="1 0.5 1 1" />
      </material>
    </visual>
    <collision>
      <origin xyz="0 0 0" rpy="0 0 0"/>
      <geometry>
        <mesh filename="" scale="1 1 1"/>
      </geometry>
    </collision>
</link>

<joint name="idx16_right_toe_roll" type="revolute">
    <origin xyz="0.0 -0.0 0.0" rpy="1.5707963 0.0 -0.0" />
    <parent link="right_toe_pitch" />
    <child link="right_toe_roll" />
    <axis xyz="0 0 1" />
    <limit lower="-0.488692182" upper="0.488692182" effort="50" velocity="12" />
</joint>

<link name="right_toe_A">
    <inertial>
      <origin xyz="9.121e-05 0.01877013 -0.00172194" rpy="0 0 0" />
      <mass value="0.06362578" />
      <inertia ixx="0.00004436" iyy="0.00001212" izz="0.00005103" ixy="4e-08" ixz="-4e-08" iyz="8e-06"/>
    </inertial>
    <visual>
      <origin xyz="0 0 0" rpy="0 0 0" />
      <geometry>
        <mesh filename="file:///home/lizhen/works/open_source/robot_model_generator/src/model_generator/robot_data/meshes/left_leg_rod1_long.STL" scale="1.0 -1.0 1.0"/>
      </geometry>
      <material name="">
        <color rgba="1 0.4 0.4 1" />
      </material>
    </visual>
    <collision>
      <origin xyz="0 0 0" rpy="0 0 0"/>
      <geometry>
        <mesh filename="" scale="1 1 1"/>
      </geometry>
    </collision>
</link>

<joint name="idx17_right_toe_A" type="fixed">
    <origin xyz="-0.138 -0.0 -0.0315" rpy="-0.0 0.0 -0.0" />
    <parent link="right_knee" />
    <child link="right_toe_A" />
    <axis xyz="0 0 1" />
    <limit lower="-1.5708" upper="1.5708" effort="0" velocity="0" />
</joint>

<link name="right_toe_A_rod">
    <inertial>
      <origin xyz="-0.1195 -0.0 -1.491e-05" rpy="0 0 0" />
      <mass value="0.08203113" />
      <inertia ixx="0.00000228" iyy="0.00078598" izz="0.00078738" ixy="-0.0" ixz="0.0" iyz="-0.0"/>
    </inertial>
    <visual>
      <origin xyz="0 0 0" rpy="0 0 0" />
      <geometry>
        <mesh filename="file:///home/lizhen/works/open_source/robot_model_generator/src/model_generator/robot_data/meshes/left_leg_rod2_long.STL" scale="1.0 -1.0 1.0"/>
      </geometry>
      <material name="">
        <color rgba="1 1 0.4 1" />
      </material>
    </visual>
    <collision>
      <origin xyz="0 0 0" rpy="0 0 0"/>
      <geometry>
        <mesh filename="" scale="1 1 1"/>
      </geometry>
    </collision>
</link>

<joint name="idx18_right_toe_A_rod" type="fixed">
    <origin xyz="0.0 0.063 0.0" rpy="-0.0 0.0 -0.0" />
    <parent link="right_toe_A" />
    <child link="right_toe_A_rod" />
    <axis xyz="0 0 1" />
    <limit lower="0" upper="0" effort="0" velocity="0" />
</joint>

<link name="right_toe_B">
    <inertial>
      <origin xyz="-9.121e-05 0.01877013 0.00172194" rpy="0 0 0" />
      <mass value="0.06362578" />
      <inertia ixx="0.00004436" iyy="0.00001212" izz="0.00005103" ixy="-4e-08" ixz="-4e-08" iyz="-8e-06"/>
    </inertial>
    <visual>
      <origin xyz="0 0 0" rpy="0 0 0" />
      <geometry>
        <mesh filename="file:///home/lizhen/works/open_source/robot_model_generator/src/model_generator/robot_data/meshes/left_leg_rod1_short.STL" scale="1.0 -1.0 1.0"/>
      </geometry>
      <material name="">
        <color rgba="0.4 1 0.4 1" />
      </material>
    </visual>
    <collision>
      <origin xyz="0 0 0" rpy="0 0 0"/>
      <geometry>
        <mesh filename="" scale="1 1 1"/>
      </geometry>
    </collision>
</link>

<joint name="idx19_right_toe_B" type="fixed">
    <origin xyz="-0.232 -0.0 0.0315" rpy="-0.0 0.0 -0.0" />
    <parent link="right_knee" />
    <child link="right_toe_B" />
    <axis xyz="0 0 1" />
    <limit lower="-1.5708" upper="1.5708" effort="0" velocity="0" />
</joint>

<link name="right_toe_B_rod">
    <inertial>
      <origin xyz="-0.0725 -6.53e-06 -2.437e-05" rpy="0 0 0" />
      <mass value="0.08225550" />
      <inertia ixx="0.00000274" iyy="0.00031414" izz="0.00031573" ixy="-0.0" ixz="0.0" iyz="-0.0"/>
    </inertial>
    <visual>
      <origin xyz="0 0 0" rpy="0 0 0" />
      <geometry>
        <mesh filename="file:///home/lizhen/works/open_source/robot_model_generator/src/model_generator/robot_data/meshes/left_leg_rod2_short.STL" scale="1.0 -1.0 1.0"/>
      </geometry>
      <material name="">
        <color rgba="0 0.5 1 1" />
      </material>
    </visual>
    <collision>
      <origin xyz="0 0 0" rpy="0 0 0"/>
      <geometry>
        <mesh filename="" scale="1 1 1"/>
      </geometry>
    </collision>
</link>

<joint name="idx20_right_toe_B_rod" type="fixed">
    <origin xyz="0.0 0.063 0.0" rpy="-0.0 0.0 -0.0" />
    <parent link="right_toe_B" />
    <child link="right_toe_B_rod" />
    <axis xyz="0 0 1" />
    <limit lower="-0.0" upper="-0.0" effort="0" velocity="0" />
</joint>

<link name="left_arm_link01">
    <inertial>
      <origin xyz="0.00000249 0.01038065 0.03761745" rpy="0 0 0" />
      <mass value="0.23884197" />
      <inertia ixx="0.00044830" iyy="0.00024895" izz="0.00040350" ixy="0" ixz="0" iyz="0.00006606"/>
    </inertial>
    <visual>
      <origin xyz="0 0 0" rpy="0 0 0" />
      <geometry>
        <mesh filename="file:///home/lizhen/works/open_source/robot_model_generator/src/model_generator/robot_data/meshes/left_arm_link01.STL" scale="1 1 1"/>
      </geometry>
      <material name="">
        <color rgba="1 0.4 0.4 1" />
      </material>
    </visual>
    <collision>
      <origin xyz="0 0 0" rpy="0 0 0"/>
      <geometry>
        <mesh filename="" scale="1 1 1"/>
      </geometry>
    </collision>
</link>

<joint name="idx21_left_arm_link01" type="revolute">
    <origin xyz="-0.03779 0.191 0.3421" rpy="1.5708 1.5708 0" />
    <parent link="base_link" />
    <child link="left_arm_link01" />
    <axis xyz="0 0 1" />
    <limit lower="-2.967" upper="2.967" effort="120" velocity="12" />
</joint>

<link name="left_arm_link02">
    <inertial>
      <origin xyz="-0.00003961 -0.05209875 -0.00115698" rpy="0 0 0" />
      <mass value="3.09638867" />
      <inertia ixx="0.01280293" iyy="0.00266575" izz="0.01264891" ixy="-0.00000268" ixz="0.00000182" iyz="0.00017645"/>
    </inertial>
    <visual>
      <origin xyz="0 0 0" rpy="0 0 0" />
      <geometry>
        <mesh filename="file:///home/lizhen/works/open_source/robot_model_generator/src/model_generator/robot_data/meshes/left_arm_link02.STL" scale="1 1 1"/>
      </geometry>
      <material name="">
        <color rgba="1 1 0.4 1" />
      </material>
    </visual>
    <collision>
      <origin xyz="0 0 0" rpy="0 0 0"/>
      <geometry>
        <mesh filename="" scale="1 1 1"/>
      </geometry>
    </collision>
</link>

<joint name="idx22_left_arm_link02" type="revolute">
    <origin xyz="0 0 0" rpy="1.5708 0 0" />
    <parent link="left_arm_link01" />
    <child link="left_arm_link02" />
    <axis xyz="0 0 1" />
    <limit lower="-0.523598767" upper="1.658062761" effort="120" velocity="12" />
</joint>

<link name="left_arm_link03">
    <inertial>
      <origin xyz="0.00000225 0.00035500 0.08376422" rpy="0 0 0" />
      <mass value="1.37452988" />
      <inertia ixx="0.00163610" iyy="0.00181828" izz="0.00109760" ixy="0.00000081" ixz="-0.00000378" iyz="0.00001043"/>
    </inertial>
    <visual>
      <origin xyz="0 0 0" rpy="0 0 0" />
      <geometry>
        <mesh filename="file:///home/lizhen/works/open_source/robot_model_generator/src/model_generator/robot_data/meshes/left_arm_link03.STL" scale="1 1 1"/>
      </geometry>
      <material name="">
        <color rgba="0.4 1 0.4 1" />
      </material>
    </visual>
    <collision>
      <origin xyz="0 0 0" rpy="0 0 0"/>
      <geometry>
        <mesh filename="" scale="1 1 1"/>
      </geometry>
    </collision>
</link>

<joint name="idx23_left_arm_link03" type="revolute">
    <origin xyz="0 -0.154 0" rpy="1.5708 0 0" />
    <parent link="left_arm_link02" />
    <child link="left_arm_link03" />
    <axis xyz="0 0 1" />
    <limit lower="-2.967" upper="2.967" effort="120" velocity="12" />
</joint>

<link name="left_arm_link04">
    <inertial>
      <origin xyz="-0.00002118 -0.07109905 -0.00481815" rpy="0 0 0" />
      <mass value="0.70457441" />
      <inertia ixx="0.00064706" iyy="0.00037557" izz="0.00056821" ixy="0.00000321" ixz="-0.00000120" iyz="0.00014782"/>
    </inertial>
    <visual>
      <origin xyz="0 0 0" rpy="0 0 0" />
      <geometry>
        <mesh filename="file:///home/lizhen/works/open_source/robot_model_generator/src/model_generator/robot_data/meshes/left_arm_link04.STL" scale="1 1 1"/>
      </geometry>
      <material name="">
        <color rgba="0 0.5 1 1" />
      </material>
    </visual>
    <collision>
      <origin xyz="0 0 0" rpy="0 0 0"/>
      <geometry>
        <mesh filename="" scale="1 1 1"/>
      </geometry>
    </collision>
</link>

<joint name="idx24_left_arm_link04" type="revolute">
    <origin xyz="0 0 0.093" rpy="-1.5708 0 1.5708" />
    <parent link="left_arm_link03" />
    <child link="left_arm_link04" />
    <axis xyz="0 0 1" />
    <limit lower="-2.094395067" upper="0" effort="120" velocity="12" />
</joint>

<link name="left_arm_link05">
    <inertial>
      <origin xyz="-0.00221884 0 0.06554799" rpy="0 0 0" />
      <mass value="0.12244729" />
      <inertia ixx="0.00031756" iyy="0.00033014" izz="0.00003000" ixy="0" ixz="0.00002042" iyz="0"/>
    </inertial>
    <visual>
      <origin xyz="0 0 0" rpy="0 0 0" />
      <geometry>
        <mesh filename="file:///home/lizhen/works/open_source/robot_model_generator/src/model_generator/robot_data/meshes/left_arm_link05.STL" scale="1 1 1"/>
      </geometry>
      <material name="">
        <color rgba="0.8 1.0 0.8 1" />
      </material>
    </visual>
    <collision>
      <origin xyz="0 0 0" rpy="0 0 0"/>
      <geometry>
        <mesh filename="" scale="1 1 1"/>
      </geometry>
    </collision>
</link>

<joint name="idx25_left_arm_link05" type="revolute">
    <origin xyz="0 -0.103 0" rpy="1.5708 0 0" />
    <parent link="left_arm_link04" />
    <child link="left_arm_link05" />
    <axis xyz="0 0 1" />
    <limit lower="-2.87979" upper="2.87979" effort="120" velocity="12" />
</joint>

<link name="left_arm_link06">
    <inertial>
      <origin xyz="0.00018011 -0.00021701 0" rpy="0 0 0" />
      <mass value="0.02504627" />
      <inertia ixx="0.00000197" iyy="0.00000173" izz="0.00000071" ixy="0" ixz="0" iyz="0"/>
    </inertial>
    <visual>
      <origin xyz="0 0 0" rpy="0 0 0" />
      <geometry>
        <mesh filename="file:///home/lizhen/works/open_source/robot_model_generator/src/model_generator/robot_data/meshes/left_arm_link06.STL" scale="1 1 1"/>
      </geometry>
      <material name="">
        <color rgba="1 0.5 1 1" />
      </material>
    </visual>
    <collision>
      <origin xyz="0 0 0" rpy="0 0 0"/>
      <geometry>
        <mesh filename="" scale="1 1 1"/>
      </geometry>
    </collision>
</link>

<joint name="idx26_left_arm_link06" type="revolute">
    <origin xyz="-0.01 0 0.1595" rpy="-1.5708 1.5708 0" />
    <parent link="left_arm_link05" />
    <child link="left_arm_link06" />
    <axis xyz="0 0 1" />
    <limit lower="-0.785398" upper="0.785398" effort="120" velocity="12" />
</joint>

<link name="left_arm_link07">
    <inertial>
      <origin xyz="-0.01211757 -0.00009712 0.00886324" rpy="0 0 0" />
      <mass value="0.05050219" />
      <inertia ixx="0.00000828" iyy="0.00001140" izz="0.00001294" ixy="0.00000006" ixz="-0.00000179" iyz="0.00000004"/>
    </inertial>
    <visual>
      <origin xyz="0 0 0" rpy="0 0 0" />
      <geometry>
        <mesh filename="file:///home/lizhen/works/open_source/robot_model_generator/src/model_generator/robot_data/meshes/left_arm_link07.STL" scale="1 1 1"/>
      </geometry>
      <material name="">
        <color rgba="1 0.4 0.4 1" />
      </material>
    </visual>
    <collision>
      <origin xyz="0 0 0" rpy="0 0 0"/>
      <geometry>
        <mesh filename="" scale="1 1 1"/>
      </geometry>
    </collision>
</link>

<joint name="idx27_left_arm_link07" type="revolute">
    <origin xyz="0 0 0" rpy="1.5708 0 0" />
    <parent link="left_arm_link06" />
    <child link="left_arm_link07" />
    <axis xyz="0 0 1" />
    <limit lower="-0.5236" upper="0.5236" effort="120" velocity="12" />
</joint>

<link name="left_wrist_motor_A">
    <inertial>
      <origin xyz="0.00013884 0.00055850 -0.05078467" rpy="0 0 0" />
      <mass value="0.22783320" />
      <inertia ixx="0.00013539" iyy="0.00013685" izz="0.00002895" ixy="0" ixz="0" iyz="0"/>
    </inertial>
    <visual>
      <origin xyz="0 0 0" rpy="0 0 0" />
      <geometry>
        <mesh filename="file:///home/lizhen/works/open_source/robot_model_generator/src/model_generator/robot_data/meshes/left_arm_wrist_motor_A.STL" scale="1 1 1"/>
      </geometry>
      <material name="">
        <color rgba="1 1 0.4 1" />
      </material>
    </visual>
    <collision>
      <origin xyz="0 0 0" rpy="0 0 0"/>
      <geometry>
        <mesh filename="" scale="1 1 1"/>
      </geometry>
    </collision>
</link>

<joint name="idx28_left_wrist_motor_A" type="fixed">
    <origin xyz="0.005 0.02245 0.0245" rpy="0 -3.126778944 0" />
    <parent link="left_arm_link05" />
    <child link="left_wrist_motor_A" />
    <axis xyz="0 0 1" />
    <limit lower="-1.5708" upper="1.5708" effort="120" velocity="12" />
</joint>

<link name="left_wrist_rod_A">
    <inertial>
      <origin xyz="-0.00000638 0.00010875 -0.00108426" rpy="0 0 0" />
      <mass value="0.01468271" />
      <inertia ixx="0.00000055" iyy="0.00000092" izz="0.00000049" ixy="0" ixz="0" iyz="0"/>
    </inertial>
    <visual>
      <origin xyz="0 0 0" rpy="0 0 0" />
      <geometry>
        <mesh filename="file:///home/lizhen/works/open_source/robot_model_generator/src/model_generator/robot_data/meshes/left_arm_wrist_rod_A.STL" scale="1 1 1"/>
      </geometry>
      <material name="">
        <color rgba="0.4 1 0.4 1" />
      </material>
    </visual>
    <collision>
      <origin xyz="0 0 0" rpy="0 0 0"/>
      <geometry>
        <mesh filename="" scale="1 1 1"/>
      </geometry>
    </collision>
</link>

<joint name="idx29_left_wrist_rod_A" type="fixed">
    <origin xyz="0 0.00055 -0.135" rpy="0 3.1415926 0" />
    <parent link="left_wrist_motor_A" />
    <child link="left_wrist_rod_A" />
    <axis xyz="0 0 1" />
    <limit lower="-0.01199" upper="0.01204" effort="120" velocity="12" />
</joint>

<link name="left_wrist_motor_B">
    <inertial>
      <origin xyz="0.00013884 0.00055850 -0.05078467" rpy="0 0 0" />
      <mass value="0.22783320" />
      <inertia ixx="0.00013539" iyy="0.00013685" izz="0.00002895" ixy="0" ixz="0" iyz="0"/>
    </inertial>
    <visual>
      <origin xyz="0 0 0" rpy="0 0 0" />
      <geometry>
        <mesh filename="file:///home/lizhen/works/open_source/robot_model_generator/src/model_generator/robot_data/meshes/left_arm_wrist_motor_A.STL" scale="1 1 1"/>
      </geometry>
      <material name="">
        <color rgba="0 0.5 1 1" />
      </material>
    </visual>
    <collision>
      <origin xyz="0 0 0" rpy="0 0 0"/>
      <geometry>
        <mesh filename="" scale="1 1 1"/>
      </geometry>
    </collision>
</link>

<joint name="idx30_left_wrist_motor_B" type="fixed">
    <origin xyz="0.005 -0.02245 0.0245" rpy="0 -3.126778944 0" />
    <parent link="left_arm_link05" />
    <child link="left_wrist_motor_B" />
    <axis xyz="0 0 1" />
    <limit lower="-1.5708" upper="1.5708" effort="120" velocity="12" />
</joint>

<link name="left_wrist_rod_B">
    <inertial>
      <origin xyz="-0.00000638 0.00010875 -0.00108426" rpy="0 0 0" />
      <mass value="0.01468271" />
      <inertia ixx="0.00000055" iyy="0.00000092" izz="0.00000049" ixy="0" ixz="0" iyz="0"/>
    </inertial>
    <visual>
      <origin xyz="0 0 0" rpy="0 0 0" />
      <geometry>
        <mesh filename="file:///home/lizhen/works/open_source/robot_model_generator/src/model_generator/robot_data/meshes/left_arm_wrist_rod_A.STL" scale="1 1 1"/>
      </geometry>
      <material name="">
        <color rgba="0.8 1.0 0.8 1" />
      </material>
    </visual>
    <collision>
      <origin xyz="0 0 0" rpy="0 0 0"/>
      <geometry>
        <mesh filename="" scale="1 1 1"/>
      </geometry>
    </collision>
</link>

<joint name="idx31_left_wrist_rod_B" type="fixed">
    <origin xyz="0 0.00055 -0.135" rpy="0 3.1415926 0" />
    <parent link="left_wrist_motor_B" />
    <child link="left_wrist_rod_B" />
    <axis xyz="0 0 1" />
    <limit lower="-0.01199" upper="0.01204" effort="120" velocity="12" />
</joint>

<link name="right_arm_link01">
    <inertial>
      <origin xyz="2.49e-06 -0.01038065 0.03761745" rpy="0 0 0" />
      <mass value="0.23884197" />
      <inertia ixx="0.00044830" iyy="0.00024895" izz="0.00040350" ixy="-0.0" ixz="0.0" iyz="-6.606e-05"/>
    </inertial>
    <visual>
      <origin xyz="0 0 0" rpy="0 0 0" />
      <geometry>
        <mesh filename="file:///home/lizhen/works/open_source/robot_model_generator/src/model_generator/robot_data/meshes/left_arm_link01.STL" scale="1.0 -1.0 1.0"/>
      </geometry>
      <material name="">
        <color rgba="1 0.4 0.4 1" />
      </material>
    </visual>
    <collision>
      <origin xyz="0 0 0" rpy="0 0 0"/>
      <geometry>
        <mesh filename="" scale="1 1 1"/>
      </geometry>
    </collision>
</link>

<joint name="idx32_right_arm_link01" type="revolute">
    <origin xyz="-0.03779 -0.191 0.3421" rpy="-1.5708 1.5708 -0.0" />
    <parent link="base_link" />
    <child link="right_arm_link01" />
    <axis xyz="0 0 1" />
    <limit lower="-2.967" upper="2.967" effort="120" velocity="12" />
</joint>

<link name="right_arm_link02">
    <inertial>
      <origin xyz="-3.961e-05 0.05209875 -0.00115698" rpy="0 0 0" />
      <mass value="3.09638867" />
      <inertia ixx="0.01280293" iyy="0.00266575" izz="0.01264891" ixy="2.68e-06" ixz="1.82e-06" iyz="-0.00017645"/>
    </inertial>
    <visual>
      <origin xyz="0 0 0" rpy="0 0 0" />
      <geometry>
        <mesh filename="file:///home/lizhen/works/open_source/robot_model_generator/src/model_generator/robot_data/meshes/left_arm_link02.STL" scale="1.0 -1.0 1.0"/>
      </geometry>
      <material name="">
        <color rgba="1 1 0.4 1" />
      </material>
    </visual>
    <collision>
      <origin xyz="0 0 0" rpy="0 0 0"/>
      <geometry>
        <mesh filename="" scale="1 1 1"/>
      </geometry>
    </collision>
</link>

<joint name="idx33_right_arm_link02" type="revolute">
    <origin xyz="0.0 -0.0 0.0" rpy="-1.5708 0.0 -0.0" />
    <parent link="right_arm_link01" />
    <child link="right_arm_link02" />
    <axis xyz="0 0 1" />
    <limit lower="-1.658062761" upper="0.523598767" effort="120" velocity="12" />
</joint>

<link name="right_arm_link03">
    <inertial>
      <origin xyz="2.25e-06 -0.000355 0.08376422" rpy="0 0 0" />
      <mass value="1.37452988" />
      <inertia ixx="0.00163610" iyy="0.00181828" izz="0.00109760" ixy="-8.1e-07" ixz="-3.78e-06" iyz="-1.043e-05"/>
    </inertial>
    <visual>
      <origin xyz="0 0 0" rpy="0 0 0" />
      <geometry>
        <mesh filename="file:///home/lizhen/works/open_source/robot_model_generator/src/model_generator/robot_data/meshes/left_arm_link03.STL" scale="1.0 -1.0 1.0"/>
      </geometry>
      <material name="">
        <color rgba="0.4 1 0.4 1" />
      </material>
    </visual>
    <collision>
      <origin xyz="0 0 0" rpy="0 0 0"/>
      <geometry>
        <mesh filename="" scale="1 1 1"/>
      </geometry>
    </collision>
</link>

<joint name="idx34_right_arm_link03" type="revolute">
    <origin xyz="0.0 0.154 0.0" rpy="-1.5708 0.0 -0.0" />
    <parent link="right_arm_link02" />
    <child link="right_arm_link03" />
    <axis xyz="0 0 1" />
    <limit lower="-2.967" upper="2.967" effort="120" velocity="12" />
</joint>

<link name="right_arm_link04">
    <inertial>
      <origin xyz="-2.118e-05 0.07109905 -0.00481815" rpy="0 0 0" />
      <mass value="0.70457441" />
      <inertia ixx="0.00064706" iyy="0.00037557" izz="0.00056821" ixy="-3.21e-06" ixz="-1.2e-06" iyz="-0.00014782"/>
    </inertial>
    <visual>
      <origin xyz="0 0 0" rpy="0 0 0" />
      <geometry>
        <mesh filename="file:///home/lizhen/works/open_source/robot_model_generator/src/model_generator/robot_data/meshes/left_arm_link04.STL" scale="1.0 -1.0 1.0"/>
      </geometry>
      <material name="">
        <color rgba="0 0.5 1 1" />
      </material>
    </visual>
    <collision>
      <origin xyz="0 0 0" rpy="0 0 0"/>
      <geometry>
        <mesh filename="" scale="1 1 1"/>
      </geometry>
    </collision>
</link>

<joint name="idx35_right_arm_link04" type="revolute">
    <origin xyz="0.0 -0.0 0.093" rpy="1.5708 0.0 -1.5708" />
    <parent link="right_arm_link03" />
    <child link="right_arm_link04" />
    <axis xyz="0 0 1" />
    <limit lower="-0.0" upper="2.094395067" effort="120" velocity="12" />
</joint>

<link name="right_arm_link05">
    <inertial>
      <origin xyz="-0.00221884 -0.0 0.06554799" rpy="0 0 0" />
      <mass value="0.12244729" />
      <inertia ixx="0.00031756" iyy="0.00033014" izz="0.00003000" ixy="-0.0" ixz="2.042e-05" iyz="-0.0"/>
    </inertial>
    <visual>
      <origin xyz="0 0 0" rpy="0 0 0" />
      <geometry>
        <mesh filename="file:///home/lizhen/works/open_source/robot_model_generator/src/model_generator/robot_data/meshes/left_arm_link05.STL" scale="1.0 -1.0 1.0"/>
      </geometry>
      <material name="">
        <color rgba="0.8 1.0 0.8 1" />
      </material>
    </visual>
    <collision>
      <origin xyz="0 0 0" rpy="0 0 0"/>
      <geometry>
        <mesh filename="" scale="1 1 1"/>
      </geometry>
    </collision>
</link>

<joint name="idx36_right_arm_link05" type="revolute">
    <origin xyz="0.0 0.103 0.0" rpy="-1.5708 0.0 -0.0" />
    <parent link="right_arm_link04" />
    <child link="right_arm_link05" />
    <axis xyz="0 0 1" />
    <limit lower="-2.87979" upper="2.87979" effort="120" velocity="12" />
</joint>

<link name="right_arm_link06">
    <inertial>
      <origin xyz="0.00018011 0.00021701 0.0" rpy="0 0 0" />
      <mass value="0.02504627" />
      <inertia ixx="0.00000197" iyy="0.00000173" izz="0.00000071" ixy="-0.0" ixz="0.0" iyz="-0.0"/>
    </inertial>
    <visual>
      <origin xyz="0 0 0" rpy="0 0 0" />
      <geometry>
        <mesh filename="file:///home/lizhen/works/open_source/robot_model_generator/src/model_generator/robot_data/meshes/left_arm_link06.STL" scale="1.0 -1.0 1.0"/>
      </geometry>
      <material name="">
        <color rgba="1 0.5 1 1" />
      </material>
    </visual>
    <collision>
      <origin xyz="0 0 0" rpy="0 0 0"/>
      <geometry>
        <mesh filename="" scale="1 1 1"/>
      </geometry>
    </collision>
</link>

<joint name="idx37_right_arm_link06" type="revolute">
    <origin xyz="-0.01 -0.0 0.1595" rpy="1.5708 1.5708 -0.0" />
    <parent link="right_arm_link05" />
    <child link="right_arm_link06" />
    <axis xyz="0 0 1" />
    <limit lower="-0.785398" upper="0.785398" effort="120" velocity="12" />
</joint>

<link name="right_arm_link07">
    <inertial>
      <origin xyz="-0.01211757 9.712e-05 0.00886324" rpy="0 0 0" />
      <mass value="0.05050219" />
      <inertia ixx="0.00000828" iyy="0.00001140" izz="0.00001294" ixy="-6e-08" ixz="-1.79e-06" iyz="-4e-08"/>
    </inertial>
    <visual>
      <origin xyz="0 0 0" rpy="0 0 0" />
      <geometry>
        <mesh filename="file:///home/lizhen/works/open_source/robot_model_generator/src/model_generator/robot_data/meshes/left_arm_link07.STL" scale="1.0 -1.0 1.0"/>
      </geometry>
      <material name="">
        <color rgba="1 0.4 0.4 1" />
      </material>
    </visual>
    <collision>
      <origin xyz="0 0 0" rpy="0 0 0"/>
      <geometry>
        <mesh filename="" scale="1 1 1"/>
      </geometry>
    </collision>
</link>

<joint name="idx38_right_arm_link07" type="revolute">
    <origin xyz="0.0 -0.0 0.0" rpy="-1.5708 0.0 -0.0" />
    <parent link="right_arm_link06" />
    <child link="right_arm_link07" />
    <axis xyz="0 0 1" />
    <limit lower="-0.5236" upper="0.5236" effort="120" velocity="12" />
</joint>

<link name="right_wrist_motor_A">
    <inertial>
      <origin xyz="0.00013884 -0.0005585 -0.05078467" rpy="0 0 0" />
      <mass value="0.22783320" />
      <inertia ixx="0.00013539" iyy="0.00013685" izz="0.00002895" ixy="-0.0" ixz="0.0" iyz="-0.0"/>
    </inertial>
    <visual>
      <origin xyz="0 0 0" rpy="0 0 0" />
      <geometry>
        <mesh filename="file:///home/lizhen/works/open_source/robot_model_generator/src/model_generator/robot_data/meshes/left_arm_wrist_motor_A.STL" scale="1.0 -1.0 1.0"/>
      </geometry>
      <material name="">
        <color rgba="1 1 0.4 1" />
      </material>
    </visual>
    <collision>
      <origin xyz="0 0 0" rpy="0 0 0"/>
      <geometry>
        <mesh filename="" scale="1 1 1"/>
      </geometry>
    </collision>
</link>

<joint name="idx39_right_wrist_motor_A" type="fixed">
    <origin xyz="0.005 -0.02245 0.0245" rpy="-0.0 -3.126778944 -0.0" />
    <parent link="right_arm_link05" />
    <child link="right_wrist_motor_A" />
    <axis xyz="0 0 1" />
    <limit lower="-1.5708" upper="1.5708" effort="120" velocity="12" />
</joint>

<link name="right_wrist_rod_A">
    <inertial>
      <origin xyz="-6.38e-06 -0.00010875 -0.00108426" rpy="0 0 0" />
      <mass value="0.01468271" />
      <inertia ixx="0.00000055" iyy="0.00000092" izz="0.00000049" ixy="-0.0" ixz="0.0" iyz="-0.0"/>
    </inertial>
    <visual>
      <origin xyz="0 0 0" rpy="0 0 0" />
      <geometry>
        <mesh filename="file:///home/lizhen/works/open_source/robot_model_generator/src/model_generator/robot_data/meshes/left_arm_wrist_rod_A.STL" scale="1.0 -1.0 1.0"/>
      </geometry>
      <material name="">
        <color rgba="0.4 1 0.4 1" />
      </material>
    </visual>
    <collision>
      <origin xyz="0 0 0" rpy="0 0 0"/>
      <geometry>
        <mesh filename="" scale="1 1 1"/>
      </geometry>
    </collision>
</link>

<joint name="idx40_right_wrist_rod_A" type="fixed">
    <origin xyz="0.0 -0.00055 -0.135" rpy="-0.0 3.1415926 -0.0" />
    <parent link="right_wrist_motor_A" />
    <child link="right_wrist_rod_A" />
    <axis xyz="0 0 1" />
    <limit lower="-0.01204" upper="0.01199" effort="120" velocity="12" />
</joint>

<link name="right_wrist_motor_B">
    <inertial>
      <origin xyz="0.00013884 -0.0005585 -0.05078467" rpy="0 0 0" />
      <mass value="0.22783320" />
      <inertia ixx="0.00013539" iyy="0.00013685" izz="0.00002895" ixy="-0.0" ixz="0.0" iyz="-0.0"/>
    </inertial>
    <visual>
      <origin xyz="0 0 0" rpy="0 0 0" />
      <geometry>
        <mesh filename="file:///home/lizhen/works/open_source/robot_model_generator/src/model_generator/robot_data/meshes/left_arm_wrist_motor_A.STL" scale="1.0 -1.0 1.0"/>
      </geometry>
      <material name="">
        <color rgba="0 0.5 1 1" />
      </material>
    </visual>
    <collision>
      <origin xyz="0 0 0" rpy="0 0 0"/>
      <geometry>
        <mesh filename="" scale="1 1 1"/>
      </geometry>
    </collision>
</link>

<joint name="idx41_right_wrist_motor_B" type="fixed">
    <origin xyz="0.005 0.02245 0.0245" rpy="-0.0 -3.126778944 -0.0" />
    <parent link="right_arm_link05" />
    <child link="right_wrist_motor_B" />
    <axis xyz="0 0 1" />
    <limit lower="-1.5708" upper="1.5708" effort="120" velocity="12" />
</joint>

<link name="right_wrist_rod_B">
    <inertial>
      <origin xyz="-6.38e-06 -0.00010875 -0.00108426" rpy="0 0 0" />
      <mass value="0.01468271" />
      <inertia ixx="0.00000055" iyy="0.00000092" izz="0.00000049" ixy="-0.0" ixz="0.0" iyz="-0.0"/>
    </inertial>
    <visual>
      <origin xyz="0 0 0" rpy="0 0 0" />
      <geometry>
        <mesh filename="file:///home/lizhen/works/open_source/robot_model_generator/src/model_generator/robot_data/meshes/left_arm_wrist_rod_A.STL" scale="1.0 -1.0 1.0"/>
      </geometry>
      <material name="">
        <color rgba="0.8 1.0 0.8 1" />
      </material>
    </visual>
    <collision>
      <origin xyz="0 0 0" rpy="0 0 0"/>
      <geometry>
        <mesh filename="" scale="1 1 1"/>
      </geometry>
    </collision>
</link>

<joint name="idx42_right_wrist_rod_B" type="fixed">
    <origin xyz="0.0 -0.00055 -0.135" rpy="-0.0 3.1415926 -0.0" />
    <parent link="right_wrist_motor_B" />
    <child link="right_wrist_rod_B" />
    <axis xyz="0 0 1" />
    <limit lower="-0.01204" upper="0.01199" effort="120" velocity="12" />
</joint>

<!-- urdf auto generate tool -->
</robot>
